2021-07-29 23:53:45,323 ERROR -> in command: prefix set
Traceback (most recent call last):
  File "C:\Users\ryanz\AppData\Local\Programs\Python\Python39\lib\site-packages\discord\ext\commands\core.py", line 85, in wrapped
    ret = await coro(*args, **kwargs)
  File "c:\Users\ryanz\OneDrive\Desktop\Table-BOT\cogs\Settings.py", line 54, in _set
    mes = self.bot.set_prefix(ctx.guild.id, prefix)
  File "c:\Users\ryanz\OneDrive\Desktop\Table-BOT\bot.py", line 192, in set_prefix
    return f"All prefixes have been removed. Use my mention, {self.bot.mention}, as a prefix."
AttributeError: 'TableBOT' object has no attribute 'bot'


2021-07-29 23:55:26,386 ERROR -> in command: prefix set
Traceback (most recent call last):
  File "C:\Users\ryanz\AppData\Local\Programs\Python\Python39\lib\site-packages\discord\ext\commands\core.py", line 85, in wrapped
    ret = await coro(*args, **kwargs)
  File "c:\Users\ryanz\OneDrive\Desktop\Table-BOT\cogs\Settings.py", line 54, in _set
    mes = self.bot.set_prefix(ctx.guild.id, prefix)
  File "c:\Users\ryanz\OneDrive\Desktop\Table-BOT\bot.py", line 192, in set_prefix
    return f"All prefixes have been removed. Use my mention, {self.mention}, as a prefix."
AttributeError: 'TableBOT' object has no attribute 'mention'


